<?xml version="1.0"?><robot name="pepe">
	<link name="0">
		<visual>
			<geometry>
				<cylinder length="0.009057844543907345" radius="0.7629075725563641"/>
			</geometry>
		</visual>
		<collision>
			<geometry>
				<cylinder length="0.009057844543907345" radius="0.7629075725563641"/>
			</geometry>
		</collision>
		<inertial>
			<mass value="0.016562221436832083"/>
			<inertia ixx="0.03" iyy="0.03" izz="0.03" ixy="0" ixz="0" iyx="0"/>
		</inertial>
	</link>
	<link name="11">
		<visual>
			<geometry>
				<box size="0.2525164925054415 0.2525164925054415 1.1668634471253905"/>
			</geometry>
		</visual>
		<collision>
			<geometry>
				<box size="0.2525164925054415 0.2525164925054415 1.1668634471253905"/>
			</geometry>
		</collision>
		<inertial>
			<mass value="0.05843720197760504"/>
			<inertia ixx="0.03" iyy="0.03" izz="0.03" ixy="0" ixz="0" iyx="0"/>
		</inertial>
	</link>
	<link name="22">
		<visual>
			<geometry>
				<box size="1.4246017300798173 1.4246017300798173 0.9221828122795191"/>
			</geometry>
		</visual>
		<collision>
			<geometry>
				<box size="1.4246017300798173 1.4246017300798173 0.9221828122795191"/>
			</geometry>
		</collision>
		<inertial>
			<mass value="1.469920476335954"/>
			<inertia ixx="0.03" iyy="0.03" izz="0.03" ixy="0" ixz="0" iyx="0"/>
		</inertial>
	</link>
	<link name="43">
		<visual>
			<geometry>
				<box size="0.7565417280677009 0.7565417280677009 1.2765294304110082"/>
			</geometry>
		</visual>
		<collision>
			<geometry>
				<box size="0.7565417280677009 0.7565417280677009 1.2765294304110082"/>
			</geometry>
		</collision>
		<inertial>
			<mass value="0.5738342783156067"/>
			<inertia ixx="0.03" iyy="0.03" izz="0.03" ixy="0" ixz="0" iyx="0"/>
		</inertial>
	</link>
	<link name="44">
		<visual>
			<geometry>
				<box size="0.7565417280677009 0.7565417280677009 1.2765294304110082"/>
			</geometry>
		</visual>
		<collision>
			<geometry>
				<box size="0.7565417280677009 0.7565417280677009 1.2765294304110082"/>
			</geometry>
		</collision>
		<inertial>
			<mass value="0.5738342783156067"/>
			<inertia ixx="0.03" iyy="0.03" izz="0.03" ixy="0" ixz="0" iyx="0"/>
		</inertial>
	</link>
	<link name="45">
		<visual>
			<geometry>
				<box size="0.7565417280677009 0.7565417280677009 1.2765294304110082"/>
			</geometry>
		</visual>
		<collision>
			<geometry>
				<box size="0.7565417280677009 0.7565417280677009 1.2765294304110082"/>
			</geometry>
		</collision>
		<inertial>
			<mass value="0.5738342783156067"/>
			<inertia ixx="0.03" iyy="0.03" izz="0.03" ixy="0" ixz="0" iyx="0"/>
		</inertial>
	</link>
	<link name="26">
		<visual>
			<geometry>
				<box size="1.4246017300798173 1.4246017300798173 0.9221828122795191"/>
			</geometry>
		</visual>
		<collision>
			<geometry>
				<box size="1.4246017300798173 1.4246017300798173 0.9221828122795191"/>
			</geometry>
		</collision>
		<inertial>
			<mass value="1.469920476335954"/>
			<inertia ixx="0.03" iyy="0.03" izz="0.03" ixy="0" ixz="0" iyx="0"/>
		</inertial>
	</link>
	<link name="47">
		<visual>
			<geometry>
				<box size="0.7565417280677009 0.7565417280677009 1.2765294304110082"/>
			</geometry>
		</visual>
		<collision>
			<geometry>
				<box size="0.7565417280677009 0.7565417280677009 1.2765294304110082"/>
			</geometry>
		</collision>
		<inertial>
			<mass value="0.5738342783156067"/>
			<inertia ixx="0.03" iyy="0.03" izz="0.03" ixy="0" ixz="0" iyx="0"/>
		</inertial>
	</link>
	<link name="48">
		<visual>
			<geometry>
				<box size="0.7565417280677009 0.7565417280677009 1.2765294304110082"/>
			</geometry>
		</visual>
		<collision>
			<geometry>
				<box size="0.7565417280677009 0.7565417280677009 1.2765294304110082"/>
			</geometry>
		</collision>
		<inertial>
			<mass value="0.5738342783156067"/>
			<inertia ixx="0.03" iyy="0.03" izz="0.03" ixy="0" ixz="0" iyx="0"/>
		</inertial>
	</link>
	<link name="49">
		<visual>
			<geometry>
				<box size="0.7565417280677009 0.7565417280677009 1.2765294304110082"/>
			</geometry>
		</visual>
		<collision>
			<geometry>
				<box size="0.7565417280677009 0.7565417280677009 1.2765294304110082"/>
			</geometry>
		</collision>
		<inertial>
			<mass value="0.5738342783156067"/>
			<inertia ixx="0.03" iyy="0.03" izz="0.03" ixy="0" ixz="0" iyx="0"/>
		</inertial>
	</link>
	<link name="210">
		<visual>
			<geometry>
				<box size="1.4246017300798173 1.4246017300798173 0.9221828122795191"/>
			</geometry>
		</visual>
		<collision>
			<geometry>
				<box size="1.4246017300798173 1.4246017300798173 0.9221828122795191"/>
			</geometry>
		</collision>
		<inertial>
			<mass value="1.469920476335954"/>
			<inertia ixx="0.03" iyy="0.03" izz="0.03" ixy="0" ixz="0" iyx="0"/>
		</inertial>
	</link>
	<link name="411">
		<visual>
			<geometry>
				<box size="0.7565417280677009 0.7565417280677009 1.2765294304110082"/>
			</geometry>
		</visual>
		<collision>
			<geometry>
				<box size="0.7565417280677009 0.7565417280677009 1.2765294304110082"/>
			</geometry>
		</collision>
		<inertial>
			<mass value="0.5738342783156067"/>
			<inertia ixx="0.03" iyy="0.03" izz="0.03" ixy="0" ixz="0" iyx="0"/>
		</inertial>
	</link>
	<link name="412">
		<visual>
			<geometry>
				<box size="0.7565417280677009 0.7565417280677009 1.2765294304110082"/>
			</geometry>
		</visual>
		<collision>
			<geometry>
				<box size="0.7565417280677009 0.7565417280677009 1.2765294304110082"/>
			</geometry>
		</collision>
		<inertial>
			<mass value="0.5738342783156067"/>
			<inertia ixx="0.03" iyy="0.03" izz="0.03" ixy="0" ixz="0" iyx="0"/>
		</inertial>
	</link>
	<link name="413">
		<visual>
			<geometry>
				<box size="0.7565417280677009 0.7565417280677009 1.2765294304110082"/>
			</geometry>
		</visual>
		<collision>
			<geometry>
				<box size="0.7565417280677009 0.7565417280677009 1.2765294304110082"/>
			</geometry>
		</collision>
		<inertial>
			<mass value="0.5738342783156067"/>
			<inertia ixx="0.03" iyy="0.03" izz="0.03" ixy="0" ixz="0" iyx="0"/>
		</inertial>
	</link>
	<link name="314">
		<visual>
			<geometry>
				<box size="0.05386615729813338 0.05386615729813338 1.40293004860074"/>
			</geometry>
		</visual>
		<collision>
			<geometry>
				<box size="0.05386615729813338 0.05386615729813338 1.40293004860074"/>
			</geometry>
		</collision>
		<inertial>
			<mass value="0.0031971122794980603"/>
			<inertia ixx="0.03" iyy="0.03" izz="0.03" ixy="0" ixz="0" iyx="0"/>
		</inertial>
	</link>
	<joint name="11_to_0" type="revolute">
		<parent link="0"/>
		<child link="11"/>
		<axis xyz="0 0 1"/>
		<limit effort="1" upper="-3.1415" lower="3.1415" velocity="1"/>
		<origin rpy="6.623305055309696 2.0355958124422133 1.1957713899188829" xyz="0.9739137415158122 0.9999 0.9753723564264214"/>
	</joint>
	<joint name="22_to_11" type="revolute">
		<parent link="11"/>
		<child link="22"/>
		<axis xyz="1 0 0"/>
		<limit effort="1" upper="-3.1415" lower="3.1415" velocity="1"/>
		<origin rpy="2.7437206674508094 2.2733772407708366 1.2236154125144392" xyz="0.9999 0.44850076168047337 0.26165231731438815"/>
	</joint>
	<joint name="43_to_22" type="revolute">
		<parent link="22"/>
		<child link="43"/>
		<axis xyz="0 1 0"/>
		<limit effort="1" upper="-3.1415" lower="3.1415" velocity="1"/>
		<origin rpy="9.854211496034896 3.5932832422801697 0.546684880848328" xyz="0.5320185349151316 0.5318004392589183 0.9158069914079802"/>
	</joint>
	<joint name="44_to_22" type="revolute">
		<parent link="22"/>
		<child link="44"/>
		<axis xyz="0 1 0"/>
		<limit effort="1" upper="-3.1415" lower="3.1415" velocity="1"/>
		<origin rpy="14.781317244052344 3.5932832422801697 0.546684880848328" xyz="0.5320185349151316 0.5318004392589183 0.9158069914079802"/>
	</joint>
	<joint name="45_to_22" type="revolute">
		<parent link="22"/>
		<child link="45"/>
		<axis xyz="0 1 0"/>
		<limit effort="1" upper="-3.1415" lower="3.1415" velocity="1"/>
		<origin rpy="19.708422992069792 3.5932832422801697 0.546684880848328" xyz="0.5320185349151316 0.5318004392589183 0.9158069914079802"/>
	</joint>
	<joint name="26_to_11" type="revolute">
		<parent link="11"/>
		<child link="26"/>
		<axis xyz="1 0 0"/>
		<limit effort="1" upper="-3.1415" lower="3.1415" velocity="1"/>
		<origin rpy="4.115581001176214 2.2733772407708366 1.2236154125144392" xyz="0.9999 0.44850076168047337 0.26165231731438815"/>
	</joint>
	<joint name="47_to_26" type="revolute">
		<parent link="26"/>
		<child link="47"/>
		<axis xyz="0 1 0"/>
		<limit effort="1" upper="-3.1415" lower="3.1415" velocity="1"/>
		<origin rpy="9.854211496034896 3.5932832422801697 0.546684880848328" xyz="0.5320185349151316 0.5318004392589183 0.9158069914079802"/>
	</joint>
	<joint name="48_to_26" type="revolute">
		<parent link="26"/>
		<child link="48"/>
		<axis xyz="0 1 0"/>
		<limit effort="1" upper="-3.1415" lower="3.1415" velocity="1"/>
		<origin rpy="14.781317244052344 3.5932832422801697 0.546684880848328" xyz="0.5320185349151316 0.5318004392589183 0.9158069914079802"/>
	</joint>
	<joint name="49_to_26" type="revolute">
		<parent link="26"/>
		<child link="49"/>
		<axis xyz="0 1 0"/>
		<limit effort="1" upper="-3.1415" lower="3.1415" velocity="1"/>
		<origin rpy="19.708422992069792 3.5932832422801697 0.546684880848328" xyz="0.5320185349151316 0.5318004392589183 0.9158069914079802"/>
	</joint>
	<joint name="210_to_11" type="revolute">
		<parent link="11"/>
		<child link="210"/>
		<axis xyz="1 0 0"/>
		<limit effort="1" upper="-3.1415" lower="3.1415" velocity="1"/>
		<origin rpy="5.487441334901619 2.2733772407708366 1.2236154125144392" xyz="0.9999 0.44850076168047337 0.26165231731438815"/>
	</joint>
	<joint name="411_to_210" type="revolute">
		<parent link="210"/>
		<child link="411"/>
		<axis xyz="0 1 0"/>
		<limit effort="1" upper="-3.1415" lower="3.1415" velocity="1"/>
		<origin rpy="9.854211496034896 3.5932832422801697 0.546684880848328" xyz="0.5320185349151316 0.5318004392589183 0.9158069914079802"/>
	</joint>
	<joint name="412_to_210" type="revolute">
		<parent link="210"/>
		<child link="412"/>
		<axis xyz="0 1 0"/>
		<limit effort="1" upper="-3.1415" lower="3.1415" velocity="1"/>
		<origin rpy="14.781317244052344 3.5932832422801697 0.546684880848328" xyz="0.5320185349151316 0.5318004392589183 0.9158069914079802"/>
	</joint>
	<joint name="413_to_210" type="revolute">
		<parent link="210"/>
		<child link="413"/>
		<axis xyz="0 1 0"/>
		<limit effort="1" upper="-3.1415" lower="3.1415" velocity="1"/>
		<origin rpy="19.708422992069792 3.5932832422801697 0.546684880848328" xyz="0.5320185349151316 0.5318004392589183 0.9158069914079802"/>
	</joint>
	<joint name="314_to_0" type="revolute">
		<parent link="0"/>
		<child link="314"/>
		<axis xyz="0 1 0"/>
		<limit effort="1" upper="-3.1415" lower="3.1415" velocity="1"/>
		<origin rpy="6.62830480933661 1.0083435977602198 3.580774287573142" xyz="0.533500759190922 0.9505003347875978 0.46205782805718615"/>
	</joint>
</robot>
